2020-10-08 20:52:17,651 ERROR: Exception on /fswap [GET] [in /home/mmaitland300/.virtualenvs/webproject/lib/python3.7/site-packages/flask/app.py:1761]
Traceback (most recent call last):
  File "/home/mmaitland300/.virtualenvs/webproject/lib/python3.7/site-packages/flask/app.py", line 2292, in wsgi_app
    response = self.full_dispatch_request()
  File "/home/mmaitland300/.virtualenvs/webproject/lib/python3.7/site-packages/flask/app.py", line 1815, in full_dispatch_request
    rv = self.handle_user_exception(e)
  File "/home/mmaitland300/.virtualenvs/webproject/lib/python3.7/site-packages/flask/app.py", line 1718, in handle_user_exception
    reraise(exc_type, exc_value, tb)
  File "/home/mmaitland300/.virtualenvs/webproject/lib/python3.7/site-packages/flask/_compat.py", line 35, in reraise
    raise value
  File "/home/mmaitland300/.virtualenvs/webproject/lib/python3.7/site-packages/flask/app.py", line 1813, in full_dispatch_request
    rv = self.dispatch_request()
  File "/home/mmaitland300/.virtualenvs/webproject/lib/python3.7/site-packages/flask/app.py", line 1799, in dispatch_request
    return self.view_functions[rule.endpoint](**req.view_args)
  File "/home/mmaitland300/flask/webproject/app/faceswap/faceswap.py", line 89, in swapface
    image = Image.open(current_app.config['IMGDIR'] + '/result.jpg')
  File "/home/mmaitland300/.virtualenvs/webproject/lib/python3.7/site-packages/PIL/Image.py", line 2878, in open
    fp = builtins.open(filename, "rb")
FileNotFoundError: [Errno 2] No such file or directory: 'app/faceswap/images/result.jpg'
